Workbook

Sheet INSUMOS
A1: Convenio* | B1: Número empleado | C1: Primer Apellido | D1: Segundo Apellido | E1: Primer Nombre | F1: Segundo Nombre | G1: RFC | H1: CURP | I1: Correo Electronico | J1: Rango Salarial | K1: CURP_Registrada | L1: Estado_Validacion
A2: Numerico | B2: Alfanumerico | C2: Minimo 2 Maximo 40 | D2: Minimo 2 Maximo 40 | E2: Minimo 2 Maximo 40 | F2: Minimo 2 Maximo 40 | G2: 13 posiciones | H2: 18 posiciones | I2: 40 posiciones | J2: 40 posiciones | K2: Si / No (validacion externa) | L2: Formula
B3: E001 | C3: Toxqui | D3: Hernández | E3: Roman | G3: TOHR710223RM0 | H3: TOHR710223HPLXRRM01 | I3: aschettino@actifpower.com | L3: =IF(LEN(G3)<>13,"RFC formato invalido",IF(LEN(H3)<>18,"CURP formato invalido",IF(ISERROR(SEARCH("@",I3)),"Correo invalido",IF(OR(A3="",B3="",C3="",E3="",G3="",H3="",I3=""),"Campo obligatorio vacio",IF(COUNTIF(ListaNegra!$A:$A,G3)>0,"Uno en lista negra",IF(K3="No","CURP no existe",IF(COUNTIF($G$3:$G$99,G3)>1,"Empleado repetido","OK"))))))) -> CURP formato invalido
B4: E002 | C4: Calixto | D4: Huitzil | E4: Aarón | F4: de Jesús | G4: CAHA880126TR0 | H4: CAHA880126HPLLTR08 | I4: fbautista@actia.com.mx | L4: =IF(LEN(G4)<>13,"RFC formato invalido",IF(LEN(H4)<>18,"CURP formato invalido",IF(ISERROR(SEARCH("@",I4)),"Correo invalido",IF(OR(A4="",B4="",C4="",E4="",G4="",H4="",I4=""),"Campo obligatorio vacio",IF(COUNTIF(ListaNegra!$A:$A,G4)>0,"Uno en lista negra",IF(K4="No","CURP no existe",IF(COUNTIF($G$3:$G$99,G4)>1,"Empleado repetido","OK"))))))) -> Campo obligatorio vacio
B5: E003 | C5: Meléndez | D5: Sánchez | E5: Miguel | F5: Ángel | G5: MESM690305NG0 | H5: MESM690305HPLLNG04 | I5: jdovarganes@yahoo.com.mx | L5: =IF(LEN(G5)<>13,"RFC formato invalido",IF(LEN(H5)<>18,"CURP formato invalido",IF(ISERROR(SEARCH("@",I5)),"Correo invalido",IF(OR(A5="",B5="",C5="",E5="",G5="",H5="",I5=""),"Campo obligatorio vacio",IF(COUNTIF(ListaNegra!$A:$A,G5)>0,"Uno en lista negra",IF(K5="No","CURP no existe",IF(COUNTIF($G$3:$G$99,G5)>1,"Empleado repetido","OK"))))))) -> Campo obligatorio vacio
B6: E004 | C6: Conde | D6: Hernández | E6: Yolanda | G6: COHY831207RL0 | H6: COHY831207MPLNRL00 | I6: salvador@prodigy.net.mx | L6: =IF(LEN(G6)<>13,"RFC formato invalido",IF(LEN(H6)<>18,"CURP formato invalido",IF(ISERROR(SEARCH("@",I6)),"Correo invalido",IF(OR(A6="",B6="",C6="",E6="",G6="",H6="",I6=""),"Campo obligatorio vacio",IF(COUNTIF(ListaNegra!$A:$A,G6)>0,"Uno en lista negra",IF(K6="No","CURP no existe",IF(COUNTIF($G$3:$G$99,G6)>1,"Empleado repetido","OK"))))))) -> Campo obligatorio vacio
B7: E005 | C7: Arenas | D7: Sánchez | E7: Yecenia | G7: AESY851209NC0 | H7: AESY851209MTLRNC01 | I7: lvilla@auriga-si.com | L7: =IF(LEN(G7)<>13,"RFC formato invalido",IF(LEN(H7)<>18,"CURP formato invalido",IF(ISERROR(SEARCH("@",I7)),"Correo invalido",IF(OR(A7="",B7="",C7="",E7="",G7="",H7="",I7=""),"Campo obligatorio vacio",IF(COUNTIF(ListaNegra!$A:$A,G7)>0,"Uno en lista negra",IF(K7="No","CURP no existe",IF(COUNTIF($G$3:$G$99,G7)>1,"Empleado repetido","OK"))))))) -> Campo obligatorio vacio
B8: E006 | C8: Ponce | D8: Rodríguez | E8: Patricia | G8: PORP690710DT0 | H8: PORP690710MPLNDT00 | I8: eduardo.bobadilla@avnet.com | L8: =IF(LEN(G8)<>13,"RFC formato invalido",IF(LEN(H8)<>18,"CURP formato invalido",IF(ISERROR(SEARCH("@",I8)),"Correo invalido",IF(OR(A8="",B8="",C8="",E8="",G8="",H8="",I8=""),"Campo obligatorio vacio",IF(COUNTIF(ListaNegra!$A:$A,G8)>0,"Uno en lista negra",IF(K8="No","CURP no existe",IF(COUNTIF($G$3:$G$99,G8)>1,"Empleado repetido","OK"))))))) -> Campo obligatorio vacio
B9: E007 | C9: Zempoaltecatl | D9: Melendez | E9: Hilario | G9: ZEMH730114LL0 | H9: ZEMH730114HPLMLL02 | I9: aromero@copiloto.com.mx | L9: =IF(LEN(G9)<>13,"RFC formato invalido",IF(LEN(H9)<>18,"CURP formato invalido",IF(ISERROR(SEARCH("@",I9)),"Correo invalido",IF(OR(A9="",B9="",C9="",E9="",G9="",H9="",I9=""),"Campo obligatorio vacio",IF(COUNTIF(ListaNegra!$A:$A,G9)>0,"Uno en lista negra",IF(K9="No","CURP no existe",IF(COUNTIF($G$3:$G$99,G9)>1,"Empleado repetido","OK"))))))) -> Campo obligatorio vacio
B10: E008 | C10: Castillo | D10: Coeto | E10: José | F10: Luis | G10: CACL650406TS0 | H10: CACL650406HPLSTS04 | I10: luis.orozco@electronicayservicio.com | L10: =IF(LEN(G10)<>13,"RFC formato invalido",IF(LEN(H10)<>18,"CURP formato invalido",IF(ISERROR(SEARCH("@",I10)),"Correo invalido",IF(OR(A10="",B10="",C10="",E10="",G10="",H10="",I10=""),"Campo obligatorio vacio",IF(COUNTIF(ListaNegra!$A:$A,G10)>0,"Uno en lista negra",IF(K10="No","CURP no existe",IF(COUNTIF($G$3:$G$99,G10)>1,"Empleado repetido","OK"))))))) -> Campo obligatorio vacio
B11: E009 | C11: Carmona | D11: Sandoval | E11: Yazmín | G11: CASY950410NZ0 | H11: CASY950410MPLRNZ06 | I11: electcont@hotmail.com | L11: =IF(LEN(G11)<>13,"RFC formato invalido",IF(LEN(H11)<>18,"CURP formato invalido",IF(ISERROR(SEARCH("@",I11)),"Correo invalido",IF(OR(A11="",B11="",C11="",E11="",G11="",H11="",I11=""),"Campo obligatorio vacio",IF(COUNTIF(ListaNegra!$A:$A,G11)>0,"Uno en lista negra",IF(K11="No","CURP no existe",IF(COUNTIF($G$3:$G$99,G11)>1,"Empleado repetido","OK"))))))) -> Campo obligatorio vacio
B12: E010 | C12: Perez | D12: Vargas | E12: Rosa | F12: Maria | G12: PEVR740910RS0 | H12: PEVR740910MPLRRS00 | I12: albertob3@hotmail.com | L12: =IF(LEN(G12)<>13,"RFC formato invalido",IF(LEN(H12)<>18,"CURP formato invalido",IF(ISERROR(SEARCH("@",I12)),"Correo invalido",IF(OR(A12="",B12="",C12="",E12="",G12="",H12="",I12=""),"Campo obligatorio vacio",IF(COUNTIF(ListaNegra!$A:$A,G12)>0,"Uno en lista negra",IF(K12="No","CURP no existe",IF(COUNTIF($G$3:$G$99,G12)>1,"Empleado repetido","OK"))))))) -> Campo obligatorio vacio
B13: E011 | C13: Mozencahuatzi | D13: Cadena | E13: Hermilo | G13: MOCH650601DR0 | H13: MOCH650601HPLZDR08 | I13: aespinosa@hidronica.com | L13: =IF(LEN(G13)<>13,"RFC formato invalido",IF(LEN(H13)<>18,"CURP formato invalido",IF(ISERROR(SEARCH("@",I13)),"Correo invalido",IF(OR(A13="",B13="",C13="",E13="",G13="",H13="",I13=""),"Campo obligatorio vacio",IF(COUNTIF(ListaNegra!$A:$A,G13)>0,"Uno en lista negra",IF(K13="No","CURP no existe",IF(COUNTIF($G$3:$G$99,G13)>1,"Empleado repetido","OK"))))))) -> Campo obligatorio vacio
B14: E012 | C14: Luna | D14: Guerrero | E14: Edith | F14: Aurora | G14: LUGE880727RD0 | H14: LUGE880727MPLNRD03 | I14: mgenieria@hikami.com.mx | L14: =IF(LEN(G14)<>13,"RFC formato invalido",IF(LEN(H14)<>18,"CURP formato invalido",IF(ISERROR(SEARCH("@",I14)),"Correo invalido",IF(OR(A14="",B14="",C14="",E14="",G14="",H14="",I14=""),"Campo obligatorio vacio",IF(COUNTIF(ListaNegra!$A:$A,G14)>0,"Uno en lista negra",IF(K14="No","CURP no existe",IF(COUNTIF($G$3:$G$99,G14)>1,"Empleado repetido","OK"))))))) -> Campo obligatorio vacio
B15: E013 | C15: Cabrera | D15: Juarez | E15: Francisco | G15: CAJF871201RR0 | H15: CAJF871201HPLBRR04 | I15: gerardopozo@prodigy.net.mx | L15: =IF(LEN(G15)<>13,"RFC formato invalido",IF(LEN(H15)<>18,"CURP formato invalido",IF(ISERROR(SEARCH("@",I15)),"Correo invalido",IF(OR(A15="",B15="",C15="",E15="",G15="",H15="",I15=""),"Campo obligatorio vacio",IF(COUNTIF(ListaNegra!$A:$A,G15)>0,"Uno en lista negra",IF(K15="No","CURP no existe",IF(COUNTIF($G$3:$G$99,G15)>1,"Empleado repetido","OK"))))))) -> Campo obligatorio vacio
B16: E014 | C16: Gomez | D16: Coca | E16: Francisco | F16: Alfredo | G16: GOCF861023CR0 | H16: GOCF861023HPLMCR05 | I16: inelectronic@hotmail.com | L16: =IF(LEN(G16)<>13,"RFC formato invalido",IF(LEN(H16)<>18,"CURP formato invalido",IF(ISERROR(SEARCH("@",I16)),"Correo invalido",IF(OR(A16="",B16="",C16="",E16="",G16="",H16="",I16=""),"Campo obligatorio vacio",IF(COUNTIF(ListaNegra!$A:$A,G16)>0,"Uno en lista negra",IF(K16="No","CURP no existe",IF(COUNTIF($G$3:$G$99,G16)>1,"Empleado repetido","OK"))))))) -> Campo obligatorio vacio
B17: E015 | C17: Gutierrez | D17: Vazquez | E17: Jose | F17: Oscar | G17: GUVO831130ZS0 | H17: GUVO831130HPLTZS09 | I17: descamilla@inmer.com | L17: =IF(LEN(G17)<>13,"RFC formato invalido",IF(LEN(H17)<>18,"CURP formato invalido",IF(ISERROR(SEARCH("@",I17)),"Correo invalido",IF(OR(A17="",B17="",C17="",E17="",G17="",H17="",I17=""),"Campo obligatorio vacio",IF(COUNTIF(ListaNegra!$A:$A,G17)>0,"Uno en lista negra",IF(K17="No","CURP no existe",IF(COUNTIF($G$3:$G$99,G17)>1,"Empleado repetido","OK"))))))) -> Campo obligatorio vacio
B18: E016 | C18: Licona | D18: Devia | E18: Rogelio | G18: LIDR940923VG0 | H18: LIDR940923HVZCVG02 | I18: karen.navarrete@innovamedica.com.mx | L18: =IF(LEN(G18)<>13,"RFC formato invalido",IF(LEN(H18)<>18,"CURP formato invalido",IF(ISERROR(SEARCH("@",I18)),"Correo invalido",IF(OR(A18="",B18="",C18="",E18="",G18="",H18="",I18=""),"Campo obligatorio vacio",IF(COUNTIF(ListaNegra!$A:$A,G18)>0,"Uno en lista negra",IF(K18="No","CURP no existe",IF(COUNTIF($G$3:$G$99,G18)>1,"Empleado repetido","OK"))))))) -> Campo obligatorio vacio
B19: E017 | C19: Librado | D19: López | E19: Susana | G19: LILS870130PS0 | H19: LILS870130MPLBPS01 | I19: joseluis@intec.com.mx | L19: =IF(LEN(G19)<>13,"RFC formato invalido",IF(LEN(H19)<>18,"CURP formato invalido",IF(ISERROR(SEARCH("@",I19)),"Correo invalido",IF(OR(A19="",B19="",C19="",E19="",G19="",H19="",I19=""),"Campo obligatorio vacio",IF(COUNTIF(ListaNegra!$A:$A,G19)>0,"Uno en lista negra",IF(K19="No","CURP no existe",IF(COUNTIF($G$3:$G$99,G19)>1,"Empleado repetido","OK"))))))) -> Campo obligatorio vacio
B20: E018 | C20: Sandoval | D20: Peralta | E20: Veronica | G20: SAPV851023RR0 | H20: SAPV851023MPLNRR01 | I20: irssa@prodigy.net.mx | L20: =IF(LEN(G20)<>13,"RFC formato invalido",IF(LEN(H20)<>18,"CURP formato invalido",IF(ISERROR(SEARCH("@",I20)),"Correo invalido",IF(OR(A20="",B20="",C20="",E20="",G20="",H20="",I20=""),"Campo obligatorio vacio",IF(COUNTIF(ListaNegra!$A:$A,G20)>0,"Uno en lista negra",IF(K20="No","CURP no existe",IF(COUNTIF($G$3:$G$99,G20)>1,"Empleado repetido","OK"))))))) -> Campo obligatorio vacio
B21: E019 | C21: Ipatlan | D21: Torres | E21: Victor | F21: Manuel | G21: IATV911021RC0 | H21: IATV911021HPLPRC04 | I21: irsa@axtel.net | L21: =IF(LEN(G21)<>13,"RFC formato invalido",IF(LEN(H21)<>18,"CURP formato invalido",IF(ISERROR(SEARCH("@",I21)),"Correo invalido",IF(OR(A21="",B21="",C21="",E21="",G21="",H21="",I21=""),"Campo obligatorio vacio",IF(COUNTIF(ListaNegra!$A:$A,G21)>0,"Uno en lista negra",IF(K21="No","CURP no existe",IF(COUNTIF($G$3:$G$99,G21)>1,"Empleado repetido","OK"))))))) -> Campo obligatorio vacio
B22: E020 | C22: Tenorio | D22: Rojas | E22: Marco | F22: Antonio | G22: TERM930429JR0 | H22: TERM930429HPLNJR05 | I22: import@isbmex.com | L22: =IF(LEN(G22)<>13,"RFC formato invalido",IF(LEN(H22)<>18,"CURP formato invalido",IF(ISERROR(SEARCH("@",I22)),"Correo invalido",IF(OR(A22="",B22="",C22="",E22="",G22="",H22="",I22=""),"Campo obligatorio vacio",IF(COUNTIF(ListaNegra!$A:$A,G22)>0,"Uno en lista negra",IF(K22="No","CURP no existe",IF(COUNTIF($G$3:$G$99,G22)>1,"Empleado repetido","OK"))))))) -> Campo obligatorio vacio
B23: E021 | C23: Ramirez | D23: Garcia | E23: Daniel | G23: RAGD750630RN0 | H23: RAGD750630HPLMRN01 | I23: hgarcia@kbtel.com | L23: =IF(LEN(G23)<>13,"RFC formato invalido",IF(LEN(H23)<>18,"CURP formato invalido",IF(ISERROR(SEARCH("@",I23)),"Correo invalido",IF(OR(A23="",B23="",C23="",E23="",G23="",H23="",I23=""),"Campo obligatorio vacio",IF(COUNTIF(ListaNegra!$A:$A,G23)>0,"Uno en lista negra",IF(K23="No","CURP no existe",IF(COUNTIF($G$3:$G$99,G23)>1,"Empleado repetido","OK"))))))) -> Campo obligatorio vacio
B24: E022 | C24: Morales | D24: Silva | E24: Maria | F24: Irianely | G24: MOSI890619LR0 | H24: MOSI890619MPLRLR07 | I24: cgaliciav@kokai.com.mx | L24: =IF(LEN(G24)<>13,"RFC formato invalido",IF(LEN(H24)<>18,"CURP formato invalido",IF(ISERROR(SEARCH("@",I24)),"Correo invalido",IF(OR(A24="",B24="",C24="",E24="",G24="",H24="",I24=""),"Campo obligatorio vacio",IF(COUNTIF(ListaNegra!$A:$A,G24)>0,"Uno en lista negra",IF(K24="No","CURP no existe",IF(COUNTIF($G$3:$G$99,G24)>1,"Empleado repetido","OK"))))))) -> Campo obligatorio vacio
B25: E023 | C25: Lucas | D25: Cordova | E25: Judith | F25: Viviana | G25: LUCJ671202RD1 | H25: LUCJ671202MPLCRD14 | I25: lincsamex@yahoo.com.mx | L25: =IF(LEN(G25)<>13,"RFC formato invalido",IF(LEN(H25)<>18,"CURP formato invalido",IF(ISERROR(SEARCH("@",I25)),"Correo invalido",IF(OR(A25="",B25="",C25="",E25="",G25="",H25="",I25=""),"Campo obligatorio vacio",IF(COUNTIF(ListaNegra!$A:$A,G25)>0,"Uno en lista negra",IF(K25="No","CURP no existe",IF(COUNTIF($G$3:$G$99,G25)>1,"Empleado repetido","OK"))))))) -> Campo obligatorio vacio
B26: E024 | C26: Sanjuampan | D26: Garcia | E26: Luis | F26: Ángel | G26: SAGL981031RS0 | H26: SAGL981031HPLNRS08 | I26: oserrano@lpldevelopment.com | L26: =IF(LEN(G26)<>13,"RFC formato invalido",IF(LEN(H26)<>18,"CURP formato invalido",IF(ISERROR(SEARCH("@",I26)),"Correo invalido",IF(OR(A26="",B26="",C26="",E26="",G26="",H26="",I26=""),"Campo obligatorio vacio",IF(COUNTIF(ListaNegra!$A:$A,G26)>0,"Uno en lista negra",IF(K26="No","CURP no existe",IF(COUNTIF($G$3:$G$99,G26)>1,"Empleado repetido","OK"))))))) -> Campo obligatorio vacio
B27: E025 | C27: Rojas | D27: Cuahtlapantzi | E27: Javier | G27: ROCJ660612HV0 | H27: ROCJ660612HTLJHV07 | I27: m.rojas@luxtronic.com.mx | L27: =IF(LEN(G27)<>13,"RFC formato invalido",IF(LEN(H27)<>18,"CURP formato invalido",IF(ISERROR(SEARCH("@",I27)),"Correo invalido",IF(OR(A27="",B27="",C27="",E27="",G27="",H27="",I27=""),"Campo obligatorio vacio",IF(COUNTIF(ListaNegra!$A:$A,G27)>0,"Uno en lista negra",IF(K27="No","CURP no existe",IF(COUNTIF($G$3:$G$99,G27)>1,"Empleado repetido","OK"))))))) -> Campo obligatorio vacio
B28: E026 | C28: Ramos | D28: Hernández | E28: Rafael | G28: RAHR860502RF0 | H28: RAHR860502HPLMRF00 | I28: ing_dept@margules.com.mx | L28: =IF(LEN(G28)<>13,"RFC formato invalido",IF(LEN(H28)<>18,"CURP formato invalido",IF(ISERROR(SEARCH("@",I28)),"Correo invalido",IF(OR(A28="",B28="",C28="",E28="",G28="",H28="",I28=""),"Campo obligatorio vacio",IF(COUNTIF(ListaNegra!$A:$A,G28)>0,"Uno en lista negra",IF(K28="No","CURP no existe",IF(COUNTIF($G$3:$G$99,G28)>1,"Empleado repetido","OK"))))))) -> Campo obligatorio vacio
B29: E027 | C29: Moreno | D29: Corona | E29: Alba | F29: Vanessa | G29: MOCA810312RL0 | H29: MOCA810312MPLRRL02 | I29: dzamudio@mei-telecom.com | L29: =IF(LEN(G29)<>13,"RFC formato invalido",IF(LEN(H29)<>18,"CURP formato invalido",IF(ISERROR(SEARCH("@",I29)),"Correo invalido",IF(OR(A29="",B29="",C29="",E29="",G29="",H29="",I29=""),"Campo obligatorio vacio",IF(COUNTIF(ListaNegra!$A:$A,G29)>0,"Uno en lista negra",IF(K29="No","CURP no existe",IF(COUNTIF($G$3:$G$99,G29)>1,"Empleado repetido","OK"))))))) -> Campo obligatorio vacio
B30: E028 | C30: Lopez | D30: Viveros | E30: Marco | F30: Antonio | G30: LOVM730529VR0 | H30: LOVM730529HPLPVR06 | I30: omicron_del@att.net.mx | L30: =IF(LEN(G30)<>13,"RFC formato invalido",IF(LEN(H30)<>18,"CURP formato invalido",IF(ISERROR(SEARCH("@",I30)),"Correo invalido",IF(OR(A30="",B30="",C30="",E30="",G30="",H30="",I30=""),"Campo obligatorio vacio",IF(COUNTIF(ListaNegra!$A:$A,G30)>0,"Uno en lista negra",IF(K30="No","CURP no existe",IF(COUNTIF($G$3:$G$99,G30)>1,"Empleado repetido","OK"))))))) -> Campo obligatorio vacio
B31: E029 | C31: Orea | D31: Perez | E31: Jose | F31: Daniel | G31: OEPD990816RN0 | H31: OEPD990816HPLRRN01 | I31: javiercruzc@att.net.mx | L31: =IF(LEN(G31)<>13,"RFC formato invalido",IF(LEN(H31)<>18,"CURP formato invalido",IF(ISERROR(SEARCH("@",I31)),"Correo invalido",IF(OR(A31="",B31="",C31="",E31="",G31="",H31="",I31=""),"Campo obligatorio vacio",IF(COUNTIF(ListaNegra!$A:$A,G31)>0,"Uno en lista negra",IF(K31="No","CURP no existe",IF(COUNTIF($G$3:$G$99,G31)>1,"Empleado repetido","OK"))))))) -> Campo obligatorio vacio
B32: E030 | C32: Hernandez | D32: Hernandez | E32: Gabriela | G32: HEHG770929RB1 | H32: HEHG770929MLPRRB14 | I32: biyubi@yahoo.com | L32: =IF(LEN(G32)<>13,"RFC formato invalido",IF(LEN(H32)<>18,"CURP formato invalido",IF(ISERROR(SEARCH("@",I32)),"Correo invalido",IF(OR(A32="",B32="",C32="",E32="",G32="",H32="",I32=""),"Campo obligatorio vacio",IF(COUNTIF(ListaNegra!$A:$A,G32)>0,"Uno en lista negra",IF(K32="No","CURP no existe",IF(COUNTIF($G$3:$G$99,G32)>1,"Empleado repetido","OK"))))))) -> Campo obligatorio vacio
B33: E031 | C33: Rebollo | D33: Pichardo | E33: Luis | F33: Gilberto | G33: REPL840310CS0 | H33: REPL840310HMCBCS08 | I33: rcortes@racom.com.mx | L33: =IF(LEN(G33)<>13,"RFC formato invalido",IF(LEN(H33)<>18,"CURP formato invalido",IF(ISERROR(SEARCH("@",I33)),"Correo invalido",IF(OR(A33="",B33="",C33="",E33="",G33="",H33="",I33=""),"Campo obligatorio vacio",IF(COUNTIF(ListaNegra!$A:$A,G33)>0,"Uno en lista negra",IF(K33="No","CURP no existe",IF(COUNTIF($G$3:$G$99,G33)>1,"Empleado repetido","OK"))))))) -> Campo obligatorio vacio
B34: E032 | C34: Aguilar | D34: Cote | E34: Alfredo | G34: AUCA880115TL0 | H34: AUCA880115HPLGTL02 | I34: rotecnia_micros@yahoo.com.mx | L34: =IF(LEN(G34)<>13,"RFC formato invalido",IF(LEN(H34)<>18,"CURP formato invalido",IF(ISERROR(SEARCH("@",I34)),"Correo invalido",IF(OR(A34="",B34="",C34="",E34="",G34="",H34="",I34=""),"Campo obligatorio vacio",IF(COUNTIF(ListaNegra!$A:$A,G34)>0,"Uno en lista negra",IF(K34="No","CURP no existe",IF(COUNTIF($G$3:$G$99,G34)>1,"Empleado repetido","OK"))))))) -> Campo obligatorio vacio
B35: E033 | C35: Chavez | D35: Muñoz | E35: Balam | F35: Rodolfo | G35: CAMB900422XL0 | H35: CAMB900422HPLHXL01 | I35: Gerardo.fouilloux@simexmexico.com.mx | L35: =IF(LEN(G35)<>13,"RFC formato invalido",IF(LEN(H35)<>18,"CURP formato invalido",IF(ISERROR(SEARCH("@",I35)),"Correo invalido",IF(OR(A35="",B35="",C35="",E35="",G35="",H35="",I35=""),"Campo obligatorio vacio",IF(COUNTIF(ListaNegra!$A:$A,G35)>0,"Uno en lista negra",IF(K35="No","CURP no existe",IF(COUNTIF($G$3:$G$99,G35)>1,"Empleado repetido","OK"))))))) -> Campo obligatorio vacio
B36: E034 | C36: Romero | D36: Herrera | E36: Ana | F36: Lilia | G36: ROHA760331RN0 | H36: ROHA760331MPLMRN06 | I36: cristianl@sistek.com.mx | L36: =IF(LEN(G36)<>13,"RFC formato invalido",IF(LEN(H36)<>18,"CURP formato invalido",IF(ISERROR(SEARCH("@",I36)),"Correo invalido",IF(OR(A36="",B36="",C36="",E36="",G36="",H36="",I36=""),"Campo obligatorio vacio",IF(COUNTIF(ListaNegra!$A:$A,G36)>0,"Uno en lista negra",IF(K36="No","CURP no existe",IF(COUNTIF($G$3:$G$99,G36)>1,"Empleado repetido","OK"))))))) -> Campo obligatorio vacio
B37: E035 | C37: Peraza | D37: Blanco | E37: Maura | F37: Maria | G37: PEBM690213LR0 | H37: PEBM690213MYNRLR01 | I37: cyber@solaris-digital.com | L37: =IF(LEN(G37)<>13,"RFC formato invalido",IF(LEN(H37)<>18,"CURP formato invalido",IF(ISERROR(SEARCH("@",I37)),"Correo invalido",IF(OR(A37="",B37="",C37="",E37="",G37="",H37="",I37=""),"Campo obligatorio vacio",IF(COUNTIF(ListaNegra!$A:$A,G37)>0,"Uno en lista negra",IF(K37="No","CURP no existe",IF(COUNTIF($G$3:$G$99,G37)>1,"Empleado repetido","OK"))))))) -> Campo obligatorio vacio
B38: E036 | C38: Aguilar | D38: Rodriguez | E38: Alfonso | G38: AURA791101DL0 | H38: AURA791101HPLGDL09 | I38: g.camporredondo@synergygam.com | L38: =IF(LEN(G38)<>13,"RFC formato invalido",IF(LEN(H38)<>18,"CURP formato invalido",IF(ISERROR(SEARCH("@",I38)),"Correo invalido",IF(OR(A38="",B38="",C38="",E38="",G38="",H38="",I38=""),"Campo obligatorio vacio",IF(COUNTIF(ListaNegra!$A:$A,G38)>0,"Uno en lista negra",IF(K38="No","CURP no existe",IF(COUNTIF($G$3:$G$99,G38)>1,"Empleado repetido","OK"))))))) -> Campo obligatorio vacio
B39: E037 | C39: Chavez | D39: Lomeli | E39: Erika | G39: CALE801230MR0 | H39: CALE801230MPLHMR01 | I39: alexc@complet.com.mx | L39: =IF(LEN(G39)<>13,"RFC formato invalido",IF(LEN(H39)<>18,"CURP formato invalido",IF(ISERROR(SEARCH("@",I39)),"Correo invalido",IF(OR(A39="",B39="",C39="",E39="",G39="",H39="",I39=""),"Campo obligatorio vacio",IF(COUNTIF(ListaNegra!$A:$A,G39)>0,"Uno en lista negra",IF(K39="No","CURP no existe",IF(COUNTIF($G$3:$G$99,G39)>1,"Empleado repetido","OK"))))))) -> Campo obligatorio vacio
B40: E038 | C40: Corona | D40: Juarez | E40: Jose | F40: Eduardo | G40: CXJE730318RD0 | H40: CXJE730318HPLRRD05 | I40: moisesb@complet.com.mx | L40: =IF(LEN(G40)<>13,"RFC formato invalido",IF(LEN(H40)<>18,"CURP formato invalido",IF(ISERROR(SEARCH("@",I40)),"Correo invalido",IF(OR(A40="",B40="",C40="",E40="",G40="",H40="",I40=""),"Campo obligatorio vacio",IF(COUNTIF(ListaNegra!$A:$A,G40)>0,"Uno en lista negra",IF(K40="No","CURP no existe",IF(COUNTIF($G$3:$G$99,G40)>1,"Empleado repetido","OK"))))))) -> Campo obligatorio vacio
...

Sheet ListaNegra
A1: RFC_Lista_Negra
A2: UDAX433218F1C
A3: ACGH8908380O2
A4: SIZA265423VGF
A5: MDLL940781YF9
A6: JUTL931034FOG
A7: MIOU525534EK8
